<?xml version="1.0" encoding="utf-8"?>
<!-- This URDF was automatically created by SolidWorks to URDF Exporter! Originally created by Stephen Brawner (brawner@gmail.com) 
     Commit Version: 1.5.1-0-g916b5db  Build Version: 1.5.7152.31018
     For more information, please see http://wiki.ros.org/sw_urdf_exporter -->
<robot
  name="irf">
  <link
    name="base_link">
    <inertial>
      <origin
        xyz="0.0432097515452396 0.405251577347367 -0.00299400168680138"
        rpy="0 0 0" />
      <mass
        value="10.233377644213" />
      <inertia
        ixx="0.804842864865789"
        ixy="-0.0256156799949306"
        ixz="-0.00222927366676388"
        iyy="0.834173111082281"
        iyz="0.00337573008953868"
        izz="0.0819167999324251" />
    </inertial>
    <visual>
      <origin
        xyz="0 0 0"
        rpy="0 0 0" />
      <geometry>
        <mesh
          filename="package://irf/meshes/B.STL" />
      </geometry>
      <material
        name="">
        <color
          rgba="1 1 1 1" />
      </material>
    </visual>
    <collision>
      <origin
        xyz="0 0 0"
        rpy="0 0 0" />
      <geometry>
        <mesh
          filename="package://irf/meshes/B.STL" />
      </geometry>
    </collision>
  </link>
  <link
    name="1L">
    <inertial>
      <origin
        xyz="0.095092 0.063757 0.046646"
        rpy="0 0 0" />
      <mass
        value="0.96286" />
      <inertia
        ixx="0.0025114"
        ixy="-0.00099938"
        ixz="-0.00029768"
        iyy="0.0020287"
        iyz="-0.00052712"
        izz="0.0032283" />
    </inertial>
    <visual>
      <origin
        xyz="0 0 0"
        rpy="0 0 0" />
      <geometry>
        <mesh
          filename="package://irf/meshes/1L.STL" />
      </geometry>
      <material
        name="">
        <color
          rgba="1 1 1 1" />
      </material>
    </visual>
    <collision>
      <origin
        xyz="0 0 0"
        rpy="0 0 0" />
      <geometry>
        <mesh
          filename="package://irf/meshes/1L.STL" />
      </geometry>
    </collision>
  </link>
  <joint
    name="01L"
    type="revolute">
    <origin
      xyz="-0.0057377 0.047589 0.38069"
      rpy="-0.65168 -0.39991 -0.28481" />
    <parent
      link="base_link" />
    <child
      link="1L" />
    <axis
      xyz="0.8138 0.34202 0.46985" />
    <limit
      lower="-0.9654"
      upper="0.9654"
      effort="0"
      velocity="0" />
  </joint>
  <link
    name="2L">
    <inertial>
      <origin
        xyz="0.0610667544332947 0.0013097610461078 0.0300993385685875"
        rpy="0 0 0" />
      <mass
        value="1.41045545917515" />
      <inertia
        ixx="0.00263880799476841"
        ixy="-0.00177608777138155"
        ixz="-0.000931723672554234"
        iyy="0.00657289010800137"
        iyz="-0.000326915650334568"
        izz="0.00712428675803793" />
    </inertial>
    <visual>
      <origin
        xyz="0 0 0"
        rpy="0 0 0" />
      <geometry>
        <mesh
          filename="package://irf/meshes/2L.STL" />
      </geometry>
      <material
        name="">
        <color
          rgba="1 1 1 1" />
      </material>
    </visual>
    <collision>
      <origin
        xyz="0 0 0"
        rpy="0 0 0" />
      <geometry>
        <mesh
          filename="package://irf/meshes/2L.STL" />
      </geometry>
    </collision>
  </link>
  <joint
    name="12L"
    type="revolute">
    <origin
      xyz="0.12122 0.076728 0.096038"
      rpy="-1.4686 -0.326 2.4813" />
    <parent
      link="1L" />
    <child
      link="2L" />
    <axis
      xyz="0.10678 0.70672 -0.69939" />
    <limit
      lower="0.8914"
      upper="2.06"
      effort="0"
      velocity="0" />
  </joint>
  <link
    name="3L">
    <inertial>
      <origin
        xyz="0.197984270837337 0.0835293747523087 0.0760650224676813"
        rpy="0 0 0" />
      <mass
        value="0.710813617750004" />
      <inertia
        ixx="0.000777777220300467"
        ixy="-0.000300175305443745"
        ixz="0.000207929878219907"
        iyy="0.00177392252781561"
        iyz="-2.01013356450046E-05"
        izz="0.00187544952023338" />
    </inertial>
    <visual>
      <origin
        xyz="0 0 0"
        rpy="0 0 0" />
      <geometry>
        <mesh
          filename="package://irf/meshes/3L.STL" />
      </geometry>
      <material
        name="">
        <color
          rgba="1 1 1 1" />
      </material>
    </visual>
    <collision>
      <origin
        xyz="0 0 0"
        rpy="0 0 0" />
      <geometry>
        <mesh
          filename="package://irf/meshes/3L.STL" />
      </geometry>
    </collision>
  </link>
  <joint
    name="23L"
    type="revolute">
    <origin
      xyz="0.015536 -0.018591 -0.017844"
      rpy="-0.00079928 -0.00033614 -0.00046138" />
    <parent
      link="2L" />
    <child
      link="3L" />
    <axis
      xyz="0.8138 0.34202 0.46985" />
    <limit
      lower="-0.9654"
      upper="0.9654"
      effort="0"
      velocity="0" />
  </joint>
  <link
    name="4L">
    <inertial>
      <origin
        xyz="0.0487175675538375 -0.0379552865392929 -0.00849182174280072"
        rpy="0 0 0" />
      <mass
        value="1.18079192762883" />
      <inertia
        ixx="0.00281471564575568"
        ixy="0.00103168841450297"
        ixz="0.00177027780429407"
        iyy="0.0050886154112469"
        iyz="-0.000671798238753022"
        izz="0.00430840622417132" />
    </inertial>
    <visual>
      <origin
        xyz="0 0 0"
        rpy="0 0 0" />
      <geometry>
        <mesh
          filename="package://irf/meshes/4L.STL" />
      </geometry>
      <material
        name="">
        <color
          rgba="1 1 1 1" />
      </material>
    </visual>
    <collision>
      <origin
        xyz="0 0 0"
        rpy="0 0 0" />
      <geometry>
        <mesh
          filename="package://irf/meshes/4L.STL" />
      </geometry>
    </collision>
  </link>
  <joint
    name="34L"
    type="revolute">
    <origin
      xyz="0.2295 0.061646 0.09733"
      rpy="-0.041579 0.46212 -0.47621" />
    <parent
      link="3L" />
    <child
      link="4L" />
    <axis
      xyz="0.10678 0.70672 -0.69939" />
    <limit
      lower="-1.0192"
      upper="0.77"
      effort="0"
      velocity="0" />
  </joint>
  <link
    name="5L">
    <inertial>
      <origin
        xyz="0.0349083824249974 -0.024034435513511 -0.0587362677038758"
        rpy="0 0 0" />
      <mass
        value="0.343419516713393" />
      <inertia
        ixx="0.000749998495979765"
        ixy="4.91705207040867E-05"
        ixz="0.000202915429970131"
        iyy="0.00078322174037831"
        iyz="-0.000179735339601591"
        izz="0.000342239768300716" />
    </inertial>
    <visual>
      <origin
        xyz="0 0 0"
        rpy="0 0 0" />
      <geometry>
        <mesh
          filename="package://irf/meshes/5L.STL" />
      </geometry>
      <material
        name="">
        <color
          rgba="1 1 1 1" />
      </material>
    </visual>
    <collision>
      <origin
        xyz="0 0 0"
        rpy="0 0 0" />
      <geometry>
        <mesh
          filename="package://irf/meshes/5L.STL" />
      </geometry>
    </collision>
  </link>
  <joint
    name="45L"
    type="revolute">
    <origin
      xyz="0.115196356607472 -0.0753070608732511 -0.0585084857542666"
      rpy="-0.0171887920517601 0.0189406911212764 0.0161881718975502" />
    <parent
      link="4L" />
    <child
      link="5L" />
    <axis
      xyz="0.571254638611826 -0.619332914863809 -0.538604565920834" />
    <limit
      lower="-1.6616"
      upper="1.6616"
      effort="0"
      velocity="0" />
  </joint>
  <link
    name="6L">
    <inertial>
      <origin
        xyz="0.00122768102868831 0.00533254114395265 0.0183464255060394"
        rpy="0 0 0" />
      <mass
        value="0.465741945501003" />
      <inertia
        ixx="0.000473250964262392"
        ixy="-1.62872634620573E-05"
        ixz="-5.55836676624634E-06"
        iyy="0.000461365565686226"
        iyz="-2.613467132457E-05"
        izz="0.000526117734640779" />
    </inertial>
    <visual>
      <origin
        xyz="0 0 0"
        rpy="0 0 0" />
      <geometry>
        <mesh
          filename="package://irf/meshes/6L.STL" />
      </geometry>
      <material
        name="">
        <color
          rgba="1 1 1 1" />
      </material>
    </visual>
    <collision>
      <origin
        xyz="0 0 0"
        rpy="0 0 0" />
      <geometry>
        <mesh
          filename="package://irf/meshes/6L.STL" />
      </geometry>
    </collision>
  </link>
  <joint
    name="56L"
    type="revolute">
    <origin
      xyz="0.0471728145210148 -0.0841993484533884 -0.0778791980350019"
      rpy="-0.0103654032994117 0.357314140710582 -0.357295616611069" />
    <parent
      link="5L" />
    <child
      link="6L" />
    <axis
      xyz="0.106777674107038 0.706717031146258 -0.69939228348625" />
    <limit
      lower="-0.5042"
      upper="0.7907"
      effort="0"
      velocity="0" />
  </joint>
  <link
    name="7L">
    <inertial>
      <origin
        xyz="0.0145775749188172 -0.0156460411510579 -0.0138374953785575"
        rpy="0 0 0" />
      <mass
        value="0.0309424125499957" />
      <inertia
        ixx="7.84956912990824E-06"
        ixy="-4.8157205488837E-07"
        ixz="-3.50805986591918E-07"
        iyy="7.93520057879367E-06"
        iyz="4.76208575180469E-07"
        izz="7.7095527912141E-06" />
    </inertial>
    <visual>
      <origin
        xyz="0 0 0"
        rpy="0 0 0" />
      <geometry>
        <mesh
          filename="package://irf/meshes/7L.STL" />
      </geometry>
      <material
        name="">
        <color
          rgba="1 1 1 1" />
      </material>
    </visual>
    <collision>
      <origin
        xyz="0 0 0"
        rpy="0 0 0" />
      <geometry>
        <mesh
          filename="package://irf/meshes/7L.STL" />
      </geometry>
    </collision>
  </link>
  <joint
    name="67L"
    type="revolute">
    <origin
      xyz="0.022079315069325 0.00994126089859926 0.0119864580985115"
      rpy="1.31235264605213 -0.294889504789811 -1.27042178310482" />
    <parent
      link="6L" />
    <child
      link="7L" />
    <axis
      xyz="0.571254638614449 -0.619332914870399 -0.538604565910475" />
    <limit
      lower="-1.3121"
      upper="1.3121"
      effort="0"
      velocity="0.0" />
  </joint>
  <link
    name="1R">
    <inertial>
      <origin
        xyz="0.0639742893254454 -0.0205397001720959 0.0110720168670653"
        rpy="0 0 0" />
      <mass
        value="0.92686" />
      <inertia
        ixx="0.002748"
        ixy="0.00012019"
        ixz="-0.0009761"
        iyy="0.0033"
        iyz="0.00030432"
        izz="0.0017204" />
    </inertial>
    <visual>
      <origin
        xyz="0 0 0"
        rpy="0 0 0" />
      <geometry>
        <mesh
          filename="package://irf/meshes/1R.STL" />
      </geometry>
      <material
        name="">
        <color
          rgba="1 1 1 1" />
      </material>
    </visual>
    <collision>
      <origin
        xyz="0 0 0"
        rpy="0 0 0" />
      <geometry>
        <mesh
          filename="package://irf/meshes/1R.STL" />
      </geometry>
    </collision>
  </link>
  <joint
    name="01R"
    type="revolute">
    <origin
      xyz="-0.0905970285494174 -0.0119241865590318 0.331693781179444"
      rpy="0.661249391678768 -0.407079130841712 0.287099256033239" />
    <parent
      link="base_link" />
    <child
      link="1R" />
    <axis
      xyz="0.813797681347725 -0.3420201433221 0.469846310398407" />
    <limit
      lower="-0.9654"
      upper="0.9654"
      effort="0"
      velocity="0" />
  </joint>
  <link
    name="2R">
    <inertial>
      <origin
        xyz="0.0639742893254454 -0.0205397001720959 0.0110720168670653"
        rpy="0 0 0" />
      <mass
        value="1.41053215466353" />
      <inertia
        ixx="0.00309527372756795"
        ixy="0.000210901349981174"
        ixz="-0.00233596016635195"
        iyy="0.0073001811977481"
        iyz="8.87437060326788E-05"
        izz="0.00594084345351202" />
    </inertial>
    <visual>
      <origin
        xyz="0 0 0"
        rpy="0 0 0" />
      <geometry>
        <mesh
          filename="package://irf/meshes/2R.STL" />
      </geometry>
      <material
        name="">
        <color
          rgba="1 1 1 1" />
      </material>
    </visual>
    <collision>
      <origin
        xyz="0 0 0"
        rpy="0 0 0" />
      <geometry>
        <mesh
          filename="package://irf/meshes/2R.STL" />
      </geometry>
    </collision>
  </link>
  <joint
    name="12R"
    type="revolute">
    <origin
      xyz="0.20607785829111 -0.112392243464449 0.145031664519265"
      rpy="1.47821664003411 -0.309277896876161 -2.50290546025724" />
    <parent
      link="1R" />
    <child
      link="2R" />
    <axis
      xyz="0.106777674127034 -0.706717031145236 -0.699392283484229" />
    <limit
      lower="-2.06"
      upper="-0.8914"
      effort="0"
      velocity="0" />
  </joint>
  <link
    name="3R">
    <inertial>
      <origin
        xyz="0.114182970426199 -0.0129956186602496 0.0687060955832561"
        rpy="0 0 0" />
      <mass
        value="0.718724825102295" />
      <inertia
        ixx="0.00099760544328756"
        ixy="-0.000354124156746618"
        ixz="-0.000455084676404323"
        iyy="0.00186485222572588"
        iyz="-7.98777509745565E-05"
        izz="0.00171995345193881" />
    </inertial>
    <visual>
      <origin
        xyz="0 0 0"
        rpy="0 0 0" />
      <geometry>
        <mesh
          filename="package://irf/meshes/3R.STL" />
      </geometry>
      <material
        name="">
        <color
          rgba="1 1 1 1" />
      </material>
    </visual>
    <collision>
      <origin
        xyz="0 0 0"
        rpy="0 0 0" />
      <geometry>
        <mesh
          filename="package://irf/meshes/3R.STL" />
      </geometry>
    </collision>
  </link>
  <joint
    name="23R"
    type="revolute">
    <origin
      xyz="0.0915183890471042 -0.0120186622456074 0.0275466493971784"
      rpy="-0.039448450188403 0.0160500394071166 -0.0229876231436337" />
    <parent
      link="2R" />
    <child
      link="3R" />
    <axis
      xyz="0.813797681351336 -0.34202014335914 0.469846310365191" />
    <limit
      lower="-0.9654"
      upper="0.9654"
      effort="0"
      velocity="0" />
  </joint>
  <link
    name="4R">
    <inertial>
      <origin
        xyz="0.052066776511191 0.0157894489164649 -0.0304284017404126"
        rpy="0 0 0" />
      <mass
        value="1.18080282713249" />
      <inertia
        ixx="0.00314259364468856"
        ixy="-0.00201508218075675"
        ixz="0.000618971266665444"
        iyy="0.0037443540475257"
        iyz="0.000520143088171732"
        izz="0.00532484117781641" />
    </inertial>
    <visual>
      <origin
        xyz="0 0 0"
        rpy="0 0 0" />
      <geometry>
        <mesh
          filename="package://irf/meshes/4R.STL" />
      </geometry>
      <material
        name="">
        <color
          rgba="1 1 1 1" />
      </material>
    </visual>
    <collision>
      <origin
        xyz="0 0 0"
        rpy="0 0 0" />
      <geometry>
        <mesh
          filename="package://irf/meshes/4R.STL" />
      </geometry>
    </collision>
  </link>
  <joint
    name="34R"
    type="revolute">
    <origin
      xyz="0.15236620264851 -0.0292295290745919 0.0527977154113355"
      rpy="0.0717762948550856 0.530708904391656 0.562616525117697" />
    <parent
      link="3R" />
    <child
      link="4R" />
    <axis
      xyz="0.106777674130013 -0.706717031141072 -0.699392283487982" />
    <limit
      lower="-0.64"
      upper="1.3"
      effort="0"
      velocity="0" />
  </joint>
  <link
    name="5R">
    <inertial>
      <origin
        xyz="0.0692040115916974 0.106981671857258 -0.0577571148838366"
        rpy="0 0 0" />
      <mass
        value="0.343456193438038" />
      <inertia
        ixx="0.000794474671934646"
        ixy="-0.000159191627522876"
        ixz="2.29914657096625E-05"
        iyy="0.000290564336271819"
        iyz="0.000162383904474214"
        izz="0.000790380943986039" />
    </inertial>
    <visual>
      <origin
        xyz="0 0 0"
        rpy="0 0 0" />
      <geometry>
        <mesh
          filename="package://irf/meshes/5R.STL" />
      </geometry>
      <material
        name="">
        <color
          rgba="1 1 1 1" />
      </material>
    </visual>
    <collision>
      <origin
        xyz="0 0 0"
        rpy="0 0 0" />
      <geometry>
        <mesh
          filename="package://irf/meshes/5R.STL" />
      </geometry>
    </collision>
  </link>
  <joint
    name="45R"
    type="revolute">
    <origin
      xyz="0.0713634822125091 0.0277850981332976 -0.0171808807510679"
      rpy="0.00444066455296555 0.00483466417264907 -0.00418566420803987" />
    <parent
      link="4R" />
    <child
      link="5R" />
    <axis
      xyz="0.571254638611776 0.619332914864763 -0.53860456591979" />
    <limit
      lower="-1.6616"
      upper="1.6616"
      effort="0"
      velocity="0" />
  </joint>
  <link
    name="6R">
    <inertial>
      <origin
        xyz="0.00327322421771459 -0.0188892472289734 0.00470169779707026"
        rpy="0 0 0" />
      <mass
        value="0.47028030766964" />
      <inertia
        ixx="0.000492904812453101"
        ixy="-4.31535809717165E-06"
        ixz="-1.65378405487454E-05"
        iyy="0.000530175526706953"
        iyz="1.71971255993553E-05"
        izz="0.000467508316828687" />
    </inertial>
    <visual>
      <origin
        xyz="0 0 0"
        rpy="0 0 0" />
      <geometry>
        <mesh
          filename="package://irf/meshes/6R.STL" />
      </geometry>
      <material
        name="">
        <color
          rgba="1 1 1 1" />
      </material>
    </visual>
    <collision>
      <origin
        xyz="0 0 0"
        rpy="0 0 0" />
      <geometry>
        <mesh
          filename="package://irf/meshes/6R.STL" />
      </geometry>
    </collision>
  </link>
  <joint
    name="56R"
    type="revolute">
    <origin
      xyz="0.087412497123785 0.127825707411432 -0.115818980607626"
      rpy="-0.00730342604387015 0.0604081215420703 0.0593475847532015" />
    <parent
      link="5R" />
    <child
      link="6R" />
    <axis
      xyz="0.10677767414999 -0.706717031153939 -0.69939228347193" />
    <limit
      lower="-0.5042"
      upper="0.7907"
      effort="0"
      velocity="0" />
  </joint>
  <link
    name="7R">
    <inertial>
      <origin
        xyz="0.0179570483998224 0.0195670692295885 -0.0168424515209229"
        rpy="0 0 0" />
      <mass
        value="0.0416752660026345" />
      <inertia
        ixx="1.04299799612481E-05"
        ixy="1.02543554054114E-06"
        ixz="-9.32461856719596E-07"
        iyy="1.04727947058894E-05"
        iyz="-1.04344179723226E-06"
        izz="1.03158136340792E-05" />
    </inertial>
    <visual>
      <origin
        xyz="0 0 0"
        rpy="0 0 0" />
      <geometry>
        <mesh
          filename="package://irf/meshes/7R.STL" />
      </geometry>
      <material
        name="">
        <color
          rgba="1 1 1 1" />
      </material>
    </visual>
    <collision>
      <origin
        xyz="0 0 0"
        rpy="0 0 0" />
      <geometry>
        <mesh
          filename="package://irf/meshes/7R.STL" />
      </geometry>
    </collision>
  </link>
  <joint
    name="67R"
    type="revolute">
    <origin
      xyz="0.0220793150687765 -0.00994126090174002 0.0119864580948938"
      rpy="0.666032477367434 1.15259582967801 -0.511862372677926" />
    <parent
      link="6R" />
    <child
      link="7R" />
    <axis
      xyz="0.571254638614754 0.619332914870736 -0.538604565909764" />
    <limit
      lower="-1.3121"
      upper="1.3121"
      effort="0"
      velocity="0" />
  </joint>
</robot>